<?xml version="1.0"?>

<robot name="qubo_test" xmlns:xacro="http://www.ros.org/wiki/xacro" >
  <!-- Includes -->
  <xacro:include filename="$(find uuv_descriptions)/models/common/urdf/common.urdf.xacro"/>
  <xacro:include filename="$(find uuv_sensor_plugins_ros)/urdf/sensor_snippets.xacro"/>

  <!-- Parameters -->
  <xacro:property name="debug" value="0"/>
  <xacro:property name="namespace" value="basic_qubo"/>
  <xacro:property name="prop_mesh_file" value="file://$(find uuv_descriptions)/models/rexrov/mesh/prop.dae"/>

  <!-- Qubo's mass, volume, and center of buoyancy -->
  <xacro:property name="mass" value="1862.87"/>
  <xacro:property name="volume" value="1.83826"/>
  <xacro:property name="center_of_buoyancy" value="0.0 0.0 0.3"/>

  <!-- Thruster joint and link macro -->
  <xacro:macro name="thruster_macro" params="namespace thruster_id *origin">
    <joint name="${namespace}/thruster_${thruster_id}_joint" type="continuous">
      <xacro:insert_block name="origin"/>
      <axis xyz="1 0 0"/>
      <parent link="${namespace}/base_link"/>
      <child link="${namespace}/thruster_${thruster_id}"/>
    </joint>
    <link name="${namespace}/thruster_${thruster_id}">
      <xacro:box_inertial x="0" y="0" z="0" mass="0.001">
        <origin xyz="0 0 0" rpy="0 0 0"/>
      </xacro:box_inertial>
      <visual>
        <origin rpy="0 0 0" xyz="0 0 0"/>
        <geometry>
          <mesh filename="${prop_mesh_file}" scale="1 1 1"/>
        </geometry>
      </visual>
      <collision>
        <origin xyz="0 0 0" rpy="0 ${0.5*pi} 0"/>
        <geometry>
          <cylinder length="0.000001" radius="0.000001"/>
        </geometry>
      </collision>
    </link>
    <gazebo>
      <plugin name="${namespace}_${thruster_id}_thruster_model" filename="libthruster_ros_plugin.so">
        <linkName>${namespace}/thruster_${thruster_id}</linkName>
        <jointName>${namespace}/thruster_${thruster_id}_joint</jointName>
        <thrustTopic>${namespace}/thrusters/${thruster_id}/thrust</thrustTopic>
        <inputTopic>${namespace}/thrusters/${thruster_id}/input</inputTopic>
        <dynamics>
          <type>FirstOrder</type>
          <timeConstant>0.05</timeConstant>
        </dynamics>
        <conversion>
          <type>Basic</type>
          <rotorConstant>0.00031</rotorConstant>
        </conversion>
      </plugin>
    </gazebo>
  </xacro:macro>




  <!-- size of robot to meters X = .4064Z  Y = Z = .3048 --> 
  
  
  <!-- pitch roll thrusters -->
  <!-- inches from bottom Z = .213m X1 = .149m X2 = .257m Y = .083m -->
  
  <!-- Qubo's base link. Assume a right-handed coordinate system, with x forward and z up -->
  <link name="${namespace}/base_link">
    <visual>
      <origin xyz="0 0 0" rpy="0 0 0"/>
      <geometry>
        <box size=".4064 .3048 .3048"/>
      </geometry>
    </visual>
    <collision>
      <geometry>
        <box size=".4064 .3048 .3048"/>
      </geometry>
    </collision>
    <inertial>
      <mass value="${mass}"/>
      <origin xyz="0 0 0"/>
      <inertia ixx="525.39" ixy="1.44" ixz="33.41" iyy="794.20" iyz="2.6" izz="691.23"/>
    </inertial>
  </link>

  <!-- TODO: figure out what this does -->
  <xacro:dummy_link name="${namespace}/ned_link" />
  <joint name="ned_joint" type="fixed">
    <!-- This is revolute and not static since gazebo would remove ned_link -->
    <origin xyz="0 0 0" rpy="${pi} 0 0"/>
    <parent link="${namespace}/base_link"/>
    <child link="${namespace}/ned_link"/>
    <limit effort="0" lower="0" upper="0" velocity="0"/>
  </joint>

  <!-- Set up hydrodynamic plugin -->
  <gazebo>
    <plugin name="uuv_plugin" filename="libunderwater_object_ros_plugin.so">
      <fluid_density>1028.0</fluid_density>
      <flow_velocity_topic>hydrodynamics/current_velocity</flow_velocity_topic>
      <debug>${debug}</debug>
      <link name="${namespace}/base_link">
        <neutrally_buoyant>0</neutrally_buoyant>
        <volume>${volume}</volume>
        <box>
          <width>1.0</width>
          <length>1.0</length>
          <height>1.0</height>
        </box>
        <center_of_buoyancy>${center_of_buoyancy}</center_of_buoyancy>
        <!-- Added mass: see p.28 in Berg2012 -->
        <hydrodynamic_model>
          <type>fossen</type>
          <added_mass>
             779.79 -6.8773 -103.32 8.5426 -165.54 -7.8033
            -6.8773 1222 51.29 409.44 -5.8488 62.726
              -103.32 51.29 3659.9 6.1112 -386.42 10.774
              8.5426 409.44 6.1112 534.9 -10.027 21.019
              -165.54 -5.8488 -386.42 -10.027 842.69 -1.1162
              -7.8033 62.726 10.775 21.019 -1.1162 224.32
          </added_mass>
          <!-- Linear damping: see p.31 in Berg2012 -->
          <linear_damping>-74.82 -69.48 -728.4 -268.8 -309.77 -105</linear_damping>
          <!-- Non-linear damping: see p.30 in Berg2012 -->
          <quadratic_damping>-748.22 -992.53 -1821.01 -672 -774.44 -523.27</quadratic_damping>
        </hydrodynamic_model>
      </link>
    </plugin>
  </gazebo>


  <!-- yaw thrusters - Z = 5 inches from bottom, X = 9.28 inches from center, Y = 7.87 inches from center -->
  <!-- Z = .127 X = .23 Y = .1998 -->
  
  <!-- Attach thrusters to base link using macro defined above -->

  <!-- thruster configs found here https://docs.google.com/presentation/d/1mApi5nQUcGGsAsevM-5AlKPS6-FG0kfG9tn8nH2BauY/edit#slide=id.g1d529f9e65_0_3 -->
  
  <xacro:thruster_macro namespace="${namespace}" thruster_id="0">
    <origin xyz="-0.23 -0.1998 0.127" rpy="${0*d2r} ${0*d2r} ${-45*d2r}"/>
  </xacro:thruster_macro>
  <xacro:thruster_macro namespace="${namespace}" thruster_id="1">
    <origin xyz="-0.23 0.1998 0.127" rpy="${0*d2r} ${0*d2r} ${45*d2r}"/>
  </xacro:thruster_macro>
  <xacro:thruster_macro namespace="${namespace}" thruster_id="2">
    <origin xyz="0.23 0.1998 0.127" rpy="${0*d2r} ${0*d2r} ${135*d2r}"/>
  </xacro:thruster_macro>
  <xacro:thruster_macro namespace="${namespace}" thruster_id="3">
    <origin xyz="0.23 -0.1998 0.127" rpy="${0*d2r} ${0*d2r} ${-135*d2r}"/>
  </xacro:thruster_macro>


  <!-- ${-74.53*d2r} ${53.21*d2r}" -->
  <!-- ${-105.47*d2r} ${53.21*d2r} -->
  
  
  <!-- <xacro:thruster_macro namespace="${namespace}" thruster_id="4"> -->
  <!--   <origin xyz="-0.412125 0.505415 0.129" rpy="${0*d2r} ${0*d2r} ${45*d2r}"/> -->
  <!-- </xacro:thruster_macro> -->
  <!-- <xacro:thruster_macro namespace="${namespace}" thruster_id="5"> -->
  <!--   <origin xyz="-0.412125 -0.505415 0.129" rpy="${0*d2r} ${0*d2r} ${-45*d2r}"/> -->
  <!-- </xacro:thruster_macro> -->
  <!-- <xacro:thruster_macro namespace="${namespace}" thruster_id="6"> -->
  <!--   <origin xyz="0.412125 0.505415 0.129" rpy="${0*d2r} ${0*d2r} ${135*d2r}"/> -->
  <!-- </xacro:thruster_macro> -->
  <!-- <xacro:thruster_macro namespace="${namespace}" thruster_id="7"> -->
  <!--   <origin xyz="0.412125 -0.505415 0.129" rpy="${0*d2r} ${0*d2r} ${-135*d2r}"/> -->
  <!-- </xacro:thruster_macro> -->

  <!-- Mount a 3D pose sensor -->
  <link name="${namespace}/pose_sensor_link">
    <xacro:box_inertial x="0" y="0" z="0" mass="0.01">
      <origin xyz="0 0 0" rpy="0 0 0"/>
    </xacro:box_inertial>
    <visual>
      <geometry>
        <box size="0.1 0.1 0.1"/>
      </geometry>
    </visual>
    <xacro:no_collision/>
  </link>

  <joint name="${namespace}/pose_sensor_joint" type="revolute">
    <origin xyz="0 0 0" rpy="0 0 0"/>
    <axis xyz="0 0 1"/>
    <parent link="${namespace}/base_link"/>
    <child link="${namespace}/pose_sensor_link"/>
    <limit effort="0" lower="0" upper="0" velocity="0"/>
  </joint>

  <gazebo>
    <plugin name="pose_3d_plugin" filename="libgazebo_ros_p3d.so">
      <robotNamespace>${namespace}</robotNamespace>
      <bodyName>${namespace}/base_link</bodyName>
      <topicName>pose_gt</topicName>
      <frameName>world</frameName>
      <gaussianNoise>0.0</gaussianNoise>
      <updateRate>30</updateRate>
    </plugin>
  </gazebo>

  <!-- DVL -->
  <xacro:default_dvl namespace="${namespace}" parent_link="${namespace}/base_link">
    <origin xyz="-1.4 0 -0.312" rpy="0 ${0.5*pi} 0"/>
  </xacro:default_dvl>

  <!-- Pressure  -->
  <xacro:default_pressure namespace="${namespace}" parent_link="${namespace}/base_link">
    <origin xyz="-1.32 0.5 0.85" rpy="0 0 0"/>
  </xacro:default_pressure>

  <!-- IMU  -->
  <xacro:default_imu namespace="${namespace}" parent_link="${namespace}/base_link">
    <origin xyz="0 0 0" rpy="0 0 0"/>
  </xacro:default_imu>

  <!-- Camera -->
  <xacro:default_camera namespace="${namespace}" parent_link="${namespace}/base_link">
    <origin xyz="1.15 0 0.4" rpy="0 0.6 0"/>
  </xacro:default_camera>

  <!-- Joint state publisher -->
  <xacro:default_joint_state_publisher namespace="qubo_test" update_rate="500"/>
</robot>
